{"timestamp":"2025-05-14T03:29:35.406434","level":"info","event":"DAG bundles loaded: dags-folder","logger":"airflow.dag_processing.bundles.manager.DagBundlesManager"}
{"timestamp":"2025-05-14T03:29:35.407045","level":"info","event":"Filling up the DagBag from /opt/airflow/dags/99_weather_data_generator_daily.py","logger":"airflow.models.dagbag.DagBag"}
{"timestamp":"2025-05-14T03:29:35.420201","level":"info","event":"Secrets backends loaded for worker","count":1,"backend_classes":["EnvironmentVariablesBackend"],"logger":"supervisor"}
{"timestamp":"2025-05-14T03:29:35.440308","level":"warning","event":"Pydantic serializer warnings:\n  PydanticSerializationUnexpectedValue(Expected `str` - serialized value may not be as expected [input_value={'MINIO_ROOT_USER': 'admi...KET_CURATED': 'curated'}, input_type=dict])","category":"UserWarning","filename":"/home/airflow/.local/lib/python3.12/site-packages/pydantic/main.py","lineno":463,"logger":"py.warnings"}
{"timestamp":"2025-05-14T03:29:36.519558Z","level":"error","event":"2025-05-14 03:29:36,519 - sample_data_generator.py - Line: 51 - INFO - Initialized DataGenerator with empty_rate=47.0%, error_rate=23.0%","chan":"stderr","logger":"task"}
{"timestamp":"2025-05-14T03:29:36.519890Z","level":"error","event":"2025-05-14 03:29:36,519 - sample_data_generator.py - Line: 316 - INFO - Rates: empty_rate=47.0%%, error_rate=23.0%%","chan":"stderr","logger":"task"}
{"timestamp":"2025-05-14T03:29:36.520083Z","level":"error","event":"2025-05-14 03:29:36,519 - sample_data_generator.py - Line: 324 - WARNING - Simulating empty JSON (rand=45.88<empty_rate)","chan":"stderr","logger":"task"}
{"timestamp":"2025-05-14T03:29:36.526154Z","level":"error","event":"2025-05-14 03:29:36,526 - connectionpool.py - Line: 868 - WARNING - Retrying (Retry(total=4, connect=None, read=None, redirect=None, status=None)) after connection broken by 'NewConnectionError('<urllib3.connection.HTTPConnection object at 0x7ff32240a570>: Failed to establish a new connection: [Errno 111] Connection refused')': /raw/data/weather_data_2025-05-14.json","chan":"stderr","logger":"task"}
{"timestamp":"2025-05-14T03:29:36.927499Z","level":"error","event":"2025-05-14 03:29:36,927 - connectionpool.py - Line: 868 - WARNING - Retrying (Retry(total=3, connect=None, read=None, redirect=None, status=None)) after connection broken by 'NewConnectionError('<urllib3.connection.HTTPConnection object at 0x7ff322a270b0>: Failed to establish a new connection: [Errno 111] Connection refused')': /raw/data/weather_data_2025-05-14.json","chan":"stderr","logger":"task"}
{"timestamp":"2025-05-14T03:29:37.728342Z","level":"error","event":"2025-05-14 03:29:37,728 - connectionpool.py - Line: 868 - WARNING - Retrying (Retry(total=2, connect=None, read=None, redirect=None, status=None)) after connection broken by 'NewConnectionError('<urllib3.connection.HTTPConnection object at 0x7ff322b96840>: Failed to establish a new connection: [Errno 111] Connection refused')': /raw/data/weather_data_2025-05-14.json","chan":"stderr","logger":"task"}
{"timestamp":"2025-05-14T03:29:39.329407Z","level":"error","event":"2025-05-14 03:29:39,329 - connectionpool.py - Line: 868 - WARNING - Retrying (Retry(total=1, connect=None, read=None, redirect=None, status=None)) after connection broken by 'NewConnectionError('<urllib3.connection.HTTPConnection object at 0x7ff322409c70>: Failed to establish a new connection: [Errno 111] Connection refused')': /raw/data/weather_data_2025-05-14.json","chan":"stderr","logger":"task"}
{"timestamp":"2025-05-14T03:29:42.529979Z","level":"error","event":"2025-05-14 03:29:42,529 - connectionpool.py - Line: 868 - WARNING - Retrying (Retry(total=0, connect=None, read=None, redirect=None, status=None)) after connection broken by 'NewConnectionError('<urllib3.connection.HTTPConnection object at 0x7ff322409df0>: Failed to establish a new connection: [Errno 111] Connection refused')': /raw/data/weather_data_2025-05-14.json","chan":"stderr","logger":"task"}
{"timestamp":"2025-05-14T03:29:42.577506Z","level":"error","event":"2025-05-14 03:29:42,530 - sample_data_generator.py - Line: 300 - ERROR - !! Failed to upload to MinIO - HTTPConnectionPool(host='localhost', port=9000): Max retries exceeded with url: /raw/data/weather_data_2025-05-14.json (Caused by NewConnectionError('<urllib3.connection.HTTPConnection object at 0x7ff32240a930>: Failed to establish a new connection: [Errno 111] Connection refused'))","chan":"stderr","logger":"task"}
{"timestamp":"2025-05-14T03:29:42.578320Z","level":"error","event":"2025-05-14 03:29:42,530 - sample_data_generator.py - Line: 345 - INFO - Uploaded to MinIO bucket 'raw', object 'data/weather_data_2025-05-14.json'","chan":"stderr","logger":"task"}
{"timestamp":"2025-05-14T03:29:42.606008","level":"error","event":"Task failed with exception","logger":"task","error_detail":[{"exc_type":"CalledProcessError","exc_value":"Command '['python', 'sample_data_generator.py', '--empty_rate', '47', '--error_rate', '23', '--credentials', '{\"MINIO_ROOT_USER\": \"admin\", \"MINIO_ROOT_PASSWORD\": \"admin123\", \"MINIO_ENDPOINT\": \"localhost:9000\", \"MINIO_KMS_SECRET_KEY\": \"my-minio-key:YWRtaW4xMjNhZG1pbjEyM2FkbWluMTIzYWRtaW4xMjM=\", \"MINIO_BUCKET_RAW\": \"raw\", \"MINIO_BUCKET_STAGING\": \"staging\", \"MINIO_BUCKET_CURATED\": \"curated\"}']' returned non-zero exit status 1.","exc_notes":[],"syntax_error":null,"is_cause":false,"frames":[{"filename":"/home/airflow/.local/lib/python3.12/site-packages/airflow/sdk/execution_time/task_runner.py","lineno":825,"name":"run"},{"filename":"/home/airflow/.local/lib/python3.12/site-packages/airflow/sdk/execution_time/task_runner.py","lineno":1088,"name":"_execute_task"},{"filename":"/home/airflow/.local/lib/python3.12/site-packages/airflow/sdk/bases/operator.py","lineno":408,"name":"wrapper"},{"filename":"/home/airflow/.local/lib/python3.12/site-packages/airflow/providers/standard/operators/python.py","lineno":212,"name":"execute"},{"filename":"/home/airflow/.local/lib/python3.12/site-packages/airflow/providers/standard/operators/python.py","lineno":235,"name":"execute_callable"},{"filename":"/home/airflow/.local/lib/python3.12/site-packages/airflow/sdk/execution_time/callback_runner.py","lineno":81,"name":"run"},{"filename":"/opt/airflow/dags/99_weather_data_generator_daily.py","lineno":89,"name":"run_generator"},{"filename":"/usr/local/lib/python3.12/subprocess.py","lineno":571,"name":"run"}]}]}
