{"timestamp":"2025-05-14T02:43:01.632557","level":"info","event":"DAG bundles loaded: dags-folder","logger":"airflow.dag_processing.bundles.manager.DagBundlesManager"}
{"timestamp":"2025-05-14T02:43:01.633163","level":"info","event":"Filling up the DagBag from /opt/airflow/dags/99_weather_data_generator_daily.py","logger":"airflow.models.dagbag.DagBag"}
{"timestamp":"2025-05-14T02:43:01.643669","level":"info","event":"Secrets backends loaded for worker","count":1,"backend_classes":["EnvironmentVariablesBackend"],"logger":"supervisor"}
{"timestamp":"2025-05-14T02:43:01.658883","level":"warning","event":"Pydantic serializer warnings:\n  PydanticSerializationUnexpectedValue(Expected `str` - serialized value may not be as expected [input_value={'MINIO_ROOT_USER': 'admi...KET_CURATED': 'curated'}, input_type=dict])","category":"UserWarning","filename":"/home/airflow/.local/lib/python3.12/site-packages/pydantic/main.py","lineno":463,"logger":"py.warnings"}
{"timestamp":"2025-05-14T02:43:01.850865Z","level":"error","event":"Traceback (most recent call last):","chan":"stderr","logger":"task"}
{"timestamp":"2025-05-14T02:43:01.851213Z","level":"error","event":"  File \"/opt/project/sample_data_generator.py\", line 9, in <module>","chan":"stderr","logger":"task"}
{"timestamp":"2025-05-14T02:43:01.852506Z","level":"error","event":"    from minio import Minio","chan":"stderr","logger":"task"}
{"timestamp":"2025-05-14T02:43:01.853016Z","level":"error","event":"ModuleNotFoundError: No module named 'minio'","chan":"stderr","logger":"task"}
{"timestamp":"2025-05-14T02:43:01.856538","level":"error","event":"Task failed with exception","logger":"task","error_detail":[{"exc_type":"CalledProcessError","exc_value":"Command '['python', 'sample_data_generator.py', '--empty_rate', '27', '--error_rate', '61', '--credentials', '{\"MINIO_ROOT_USER\": \"admin\", \"MINIO_ROOT_PASSWORD\": \"admin123\", \"MINIO_ENDPOINT\": \"localhost:9000\", \"MINIO_KMS_SECRET_KEY\": \"my-minio-key:YWRtaW4xMjNhZG1pbjEyM2FkbWluMTIzYWRtaW4xMjM=\", \"MINIO_BUCKET_RAW\": \"raw\", \"MINIO_BUCKET_STAGING\": \"staging\", \"MINIO_BUCKET_CURATED\": \"curated\"}']' returned non-zero exit status 1.","exc_notes":[],"syntax_error":null,"is_cause":false,"frames":[{"filename":"/home/airflow/.local/lib/python3.12/site-packages/airflow/sdk/execution_time/task_runner.py","lineno":825,"name":"run"},{"filename":"/home/airflow/.local/lib/python3.12/site-packages/airflow/sdk/execution_time/task_runner.py","lineno":1088,"name":"_execute_task"},{"filename":"/home/airflow/.local/lib/python3.12/site-packages/airflow/sdk/bases/operator.py","lineno":408,"name":"wrapper"},{"filename":"/home/airflow/.local/lib/python3.12/site-packages/airflow/providers/standard/operators/python.py","lineno":212,"name":"execute"},{"filename":"/home/airflow/.local/lib/python3.12/site-packages/airflow/providers/standard/operators/python.py","lineno":235,"name":"execute_callable"},{"filename":"/home/airflow/.local/lib/python3.12/site-packages/airflow/sdk/execution_time/callback_runner.py","lineno":81,"name":"run"},{"filename":"/opt/airflow/dags/99_weather_data_generator_daily.py","lineno":89,"name":"run_generator"},{"filename":"/usr/local/lib/python3.12/subprocess.py","lineno":571,"name":"run"}]}]}
{"timestamp":"2025-05-14T03:07:40.604177","level":"info","event":"DAG bundles loaded: dags-folder","logger":"airflow.dag_processing.bundles.manager.DagBundlesManager"}
{"timestamp":"2025-05-14T03:07:40.604671","level":"info","event":"Filling up the DagBag from /opt/airflow/dags/99_weather_data_generator_daily.py","logger":"airflow.models.dagbag.DagBag"}
{"timestamp":"2025-05-14T03:07:40.616078","level":"info","event":"Secrets backends loaded for worker","count":1,"backend_classes":["EnvironmentVariablesBackend"],"logger":"supervisor"}
{"timestamp":"2025-05-14T03:07:40.638991","level":"warning","event":"Pydantic serializer warnings:\n  PydanticSerializationUnexpectedValue(Expected `str` - serialized value may not be as expected [input_value={'MINIO_ROOT_USER': 'admi...KET_CURATED': 'curated'}, input_type=dict])","category":"UserWarning","filename":"/home/airflow/.local/lib/python3.12/site-packages/pydantic/main.py","lineno":463,"logger":"py.warnings"}
{"timestamp":"2025-05-14T03:07:43.226136Z","level":"error","event":"2025-05-14 03:07:43,225 - main.py - Line: 27 - WARNING - python-dotenv could not parse statement starting at line 24","chan":"stderr","logger":"task"}
{"timestamp":"2025-05-14T03:07:43.227249Z","level":"error","event":"2025-05-14 03:07:43,226 - main.py - Line: 27 - WARNING - python-dotenv could not parse statement starting at line 25","chan":"stderr","logger":"task"}
{"timestamp":"2025-05-14T03:07:43.227531Z","level":"error","event":"2025-05-14 03:07:43,226 - main.py - Line: 27 - WARNING - python-dotenv could not parse statement starting at line 26","chan":"stderr","logger":"task"}
{"timestamp":"2025-05-14T03:07:43.227739Z","level":"error","event":"2025-05-14 03:07:43,226 - main.py - Line: 27 - WARNING - python-dotenv could not parse statement starting at line 27","chan":"stderr","logger":"task"}
{"timestamp":"2025-05-14T03:07:43.227969Z","level":"error","event":"2025-05-14 03:07:43,226 - main.py - Line: 27 - WARNING - python-dotenv could not parse statement starting at line 28","chan":"stderr","logger":"task"}
{"timestamp":"2025-05-14T03:07:43.228189Z","level":"error","event":"2025-05-14 03:07:43,226 - main.py - Line: 27 - WARNING - python-dotenv could not parse statement starting at line 29","chan":"stderr","logger":"task"}
{"timestamp":"2025-05-14T03:07:43.228390Z","level":"error","event":"2025-05-14 03:07:43,226 - main.py - Line: 27 - WARNING - python-dotenv could not parse statement starting at line 30","chan":"stderr","logger":"task"}
{"timestamp":"2025-05-14T03:07:43.228563Z","level":"error","event":"2025-05-14 03:07:43,226 - main.py - Line: 27 - WARNING - python-dotenv could not parse statement starting at line 35","chan":"stderr","logger":"task"}
{"timestamp":"2025-05-14T03:07:43.228746Z","level":"error","event":"2025-05-14 03:07:43,226 - main.py - Line: 27 - WARNING - python-dotenv could not parse statement starting at line 36","chan":"stderr","logger":"task"}
{"timestamp":"2025-05-14T03:07:43.228887Z","level":"error","event":"2025-05-14 03:07:43,226 - main.py - Line: 27 - WARNING - python-dotenv could not parse statement starting at line 37","chan":"stderr","logger":"task"}
{"timestamp":"2025-05-14T03:07:43.229054Z","level":"error","event":"2025-05-14 03:07:43,226 - main.py - Line: 27 - WARNING - python-dotenv could not parse statement starting at line 38","chan":"stderr","logger":"task"}
{"timestamp":"2025-05-14T03:07:43.229223Z","level":"error","event":"2025-05-14 03:07:43,226 - main.py - Line: 27 - WARNING - python-dotenv could not parse statement starting at line 43","chan":"stderr","logger":"task"}
{"timestamp":"2025-05-14T03:07:43.229402Z","level":"error","event":"2025-05-14 03:07:43,226 - main.py - Line: 27 - WARNING - python-dotenv could not parse statement starting at line 44","chan":"stderr","logger":"task"}
{"timestamp":"2025-05-14T03:07:43.229563Z","level":"error","event":"2025-05-14 03:07:43,226 - main.py - Line: 27 - WARNING - python-dotenv could not parse statement starting at line 45","chan":"stderr","logger":"task"}
{"timestamp":"2025-05-14T03:07:43.229704Z","level":"error","event":"2025-05-14 03:07:43,226 - main.py - Line: 27 - WARNING - python-dotenv could not parse statement starting at line 46","chan":"stderr","logger":"task"}
{"timestamp":"2025-05-14T03:07:43.230049Z","level":"error","event":"2025-05-14 03:07:43,229 - sample_data_generator.py - Line: 40 - WARNING - empty_rate + error_rate > 100; reducing error_rate","chan":"stderr","logger":"task"}
{"timestamp":"2025-05-14T03:07:43.250771Z","level":"error","event":"2025-05-14 03:07:43,250 - sample_data_generator.py - Line: 51 - INFO - Initialized DataGenerator with empty_rate=90.0%, error_rate=10.0%","chan":"stderr","logger":"task"}
{"timestamp":"2025-05-14T03:07:43.251201Z","level":"error","event":"2025-05-14 03:07:43,250 - sample_data_generator.py - Line: 316 - INFO - Rates: empty_rate=90.0%%, error_rate=10.0%%","chan":"stderr","logger":"task"}
{"timestamp":"2025-05-14T03:07:43.251694Z","level":"error","event":"2025-05-14 03:07:43,250 - sample_data_generator.py - Line: 324 - WARNING - Simulating empty JSON (rand=15.85<empty_rate)","chan":"stderr","logger":"task"}
{"timestamp":"2025-05-14T03:07:43.258191Z","level":"error","event":"2025-05-14 03:07:43,258 - connectionpool.py - Line: 868 - WARNING - Retrying (Retry(total=4, connect=None, read=None, redirect=None, status=None)) after connection broken by 'NewConnectionError('<urllib3.connection.HTTPConnection object at 0x7fb75c8db680>: Failed to establish a new connection: [Errno 111] Connection refused')': /raw/data/weather_data_2025-05-14.json","chan":"stderr","logger":"task"}
{"timestamp":"2025-05-14T03:07:43.658906Z","level":"error","event":"2025-05-14 03:07:43,658 - connectionpool.py - Line: 868 - WARNING - Retrying (Retry(total=3, connect=None, read=None, redirect=None, status=None)) after connection broken by 'NewConnectionError('<urllib3.connection.HTTPConnection object at 0x7fb78bd612e0>: Failed to establish a new connection: [Errno 111] Connection refused')': /raw/data/weather_data_2025-05-14.json","chan":"stderr","logger":"task"}
{"timestamp":"2025-05-14T03:07:44.459622Z","level":"error","event":"2025-05-14 03:07:44,459 - connectionpool.py - Line: 868 - WARNING - Retrying (Retry(total=2, connect=None, read=None, redirect=None, status=None)) after connection broken by 'NewConnectionError('<urllib3.connection.HTTPConnection object at 0x7fb75c59c410>: Failed to establish a new connection: [Errno 111] Connection refused')': /raw/data/weather_data_2025-05-14.json","chan":"stderr","logger":"task"}
{"timestamp":"2025-05-14T03:07:46.060642Z","level":"error","event":"2025-05-14 03:07:46,060 - connectionpool.py - Line: 868 - WARNING - Retrying (Retry(total=1, connect=None, read=None, redirect=None, status=None)) after connection broken by 'NewConnectionError('<urllib3.connection.HTTPConnection object at 0x7fb75c59c4a0>: Failed to establish a new connection: [Errno 111] Connection refused')': /raw/data/weather_data_2025-05-14.json","chan":"stderr","logger":"task"}
{"timestamp":"2025-05-14T03:07:49.261501Z","level":"error","event":"2025-05-14 03:07:49,261 - connectionpool.py - Line: 868 - WARNING - Retrying (Retry(total=0, connect=None, read=None, redirect=None, status=None)) after connection broken by 'NewConnectionError('<urllib3.connection.HTTPConnection object at 0x7fb75c59a540>: Failed to establish a new connection: [Errno 111] Connection refused')': /raw/data/weather_data_2025-05-14.json","chan":"stderr","logger":"task"}
{"timestamp":"2025-05-14T03:07:49.262756Z","level":"error","event":"2025-05-14 03:07:49,261 - sample_data_generator.py - Line: 300 - ERROR - !! Failed to upload to MinIO - HTTPConnectionPool(host='localhost', port=9000): Max retries exceeded with url: /raw/data/weather_data_2025-05-14.json (Caused by NewConnectionError('<urllib3.connection.HTTPConnection object at 0x7fb75c599c40>: Failed to establish a new connection: [Errno 111] Connection refused'))","chan":"stderr","logger":"task"}
{"timestamp":"2025-05-14T03:07:49.263153Z","level":"error","event":"2025-05-14 03:07:49,261 - sample_data_generator.py - Line: 345 - INFO - Uploaded to MinIO bucket 'raw', object 'data/weather_data_2025-05-14.json'","chan":"stderr","logger":"task"}
{"timestamp":"2025-05-14T03:07:49.352651","level":"error","event":"Task failed with exception","logger":"task","error_detail":[{"exc_type":"CalledProcessError","exc_value":"Command '['python', 'sample_data_generator.py', '--empty_rate', '90', '--error_rate', '21', '--credentials', '{\"MINIO_ROOT_USER\": \"admin\", \"MINIO_ROOT_PASSWORD\": \"admin123\", \"MINIO_ENDPOINT\": \"localhost:9000\", \"MINIO_KMS_SECRET_KEY\": \"my-minio-key:YWRtaW4xMjNhZG1pbjEyM2FkbWluMTIzYWRtaW4xMjM=\", \"MINIO_BUCKET_RAW\": \"raw\", \"MINIO_BUCKET_STAGING\": \"staging\", \"MINIO_BUCKET_CURATED\": \"curated\"}']' returned non-zero exit status 1.","exc_notes":[],"syntax_error":null,"is_cause":false,"frames":[{"filename":"/home/airflow/.local/lib/python3.12/site-packages/airflow/sdk/execution_time/task_runner.py","lineno":825,"name":"run"},{"filename":"/home/airflow/.local/lib/python3.12/site-packages/airflow/sdk/execution_time/task_runner.py","lineno":1088,"name":"_execute_task"},{"filename":"/home/airflow/.local/lib/python3.12/site-packages/airflow/sdk/bases/operator.py","lineno":408,"name":"wrapper"},{"filename":"/home/airflow/.local/lib/python3.12/site-packages/airflow/providers/standard/operators/python.py","lineno":212,"name":"execute"},{"filename":"/home/airflow/.local/lib/python3.12/site-packages/airflow/providers/standard/operators/python.py","lineno":235,"name":"execute_callable"},{"filename":"/home/airflow/.local/lib/python3.12/site-packages/airflow/sdk/execution_time/callback_runner.py","lineno":81,"name":"run"},{"filename":"/opt/airflow/dags/99_weather_data_generator_daily.py","lineno":89,"name":"run_generator"},{"filename":"/usr/local/lib/python3.12/subprocess.py","lineno":571,"name":"run"}]}]}
{"timestamp":"2025-05-14T03:21:43.432009","level":"info","event":"DAG bundles loaded: dags-folder","logger":"airflow.dag_processing.bundles.manager.DagBundlesManager"}
{"timestamp":"2025-05-14T03:21:43.433000","level":"info","event":"Filling up the DagBag from /opt/airflow/dags/99_weather_data_generator_daily.py","logger":"airflow.models.dagbag.DagBag"}
{"timestamp":"2025-05-14T03:21:43.447972","level":"info","event":"Secrets backends loaded for worker","count":1,"backend_classes":["EnvironmentVariablesBackend"],"logger":"supervisor"}
{"timestamp":"2025-05-14T03:21:43.462774","level":"warning","event":"Pydantic serializer warnings:\n  PydanticSerializationUnexpectedValue(Expected `str` - serialized value may not be as expected [input_value={'MINIO_ROOT_USER': 'admi...KET_CURATED': 'curated'}, input_type=dict])","category":"UserWarning","filename":"/home/airflow/.local/lib/python3.12/site-packages/pydantic/main.py","lineno":463,"logger":"py.warnings"}
{"timestamp":"2025-05-14T03:21:46.239592Z","level":"error","event":"2025-05-14 03:21:46,239 - sample_data_generator.py - Line: 51 - INFO - Initialized DataGenerator with empty_rate=47.0%, error_rate=23.0%","chan":"stderr","logger":"task"}
{"timestamp":"2025-05-14T03:21:46.240030Z","level":"error","event":"2025-05-14 03:21:46,239 - sample_data_generator.py - Line: 316 - INFO - Rates: empty_rate=47.0%%, error_rate=23.0%%","chan":"stderr","logger":"task"}
{"timestamp":"2025-05-14T03:21:46.240224Z","level":"error","event":"2025-05-14 03:21:46,239 - sample_data_generator.py - Line: 324 - WARNING - Simulating empty JSON (rand=1.05<empty_rate)","chan":"stderr","logger":"task"}
{"timestamp":"2025-05-14T03:21:46.246523Z","level":"error","event":"2025-05-14 03:21:46,246 - connectionpool.py - Line: 868 - WARNING - Retrying (Retry(total=4, connect=None, read=None, redirect=None, status=None)) after connection broken by 'NewConnectionError('<urllib3.connection.HTTPConnection object at 0x7fbb13d65730>: Failed to establish a new connection: [Errno 111] Connection refused')': /raw/data/weather_data_2025-05-14.json","chan":"stderr","logger":"task"}
{"timestamp":"2025-05-14T03:21:46.647368Z","level":"error","event":"2025-05-14 03:21:46,647 - connectionpool.py - Line: 868 - WARNING - Retrying (Retry(total=3, connect=None, read=None, redirect=None, status=None)) after connection broken by 'NewConnectionError('<urllib3.connection.HTTPConnection object at 0x7fbae517c710>: Failed to establish a new connection: [Errno 111] Connection refused')': /raw/data/weather_data_2025-05-14.json","chan":"stderr","logger":"task"}
{"timestamp":"2025-05-14T03:21:47.448103Z","level":"error","event":"2025-05-14 03:21:47,447 - connectionpool.py - Line: 868 - WARNING - Retrying (Retry(total=2, connect=None, read=None, redirect=None, status=None)) after connection broken by 'NewConnectionError('<urllib3.connection.HTTPConnection object at 0x7fbae51e8d40>: Failed to establish a new connection: [Errno 111] Connection refused')': /raw/data/weather_data_2025-05-14.json","chan":"stderr","logger":"task"}
{"timestamp":"2025-05-14T03:21:49.048881Z","level":"error","event":"2025-05-14 03:21:49,048 - connectionpool.py - Line: 868 - WARNING - Retrying (Retry(total=1, connect=None, read=None, redirect=None, status=None)) after connection broken by 'NewConnectionError('<urllib3.connection.HTTPConnection object at 0x7fbae51e9010>: Failed to establish a new connection: [Errno 111] Connection refused')': /raw/data/weather_data_2025-05-14.json","chan":"stderr","logger":"task"}
{"timestamp":"2025-05-14T03:21:52.249948Z","level":"error","event":"2025-05-14 03:21:52,249 - connectionpool.py - Line: 868 - WARNING - Retrying (Retry(total=0, connect=None, read=None, redirect=None, status=None)) after connection broken by 'NewConnectionError('<urllib3.connection.HTTPConnection object at 0x7fbae51e9670>: Failed to establish a new connection: [Errno 111] Connection refused')': /raw/data/weather_data_2025-05-14.json","chan":"stderr","logger":"task"}
{"timestamp":"2025-05-14T03:21:52.250852Z","level":"error","event":"2025-05-14 03:21:52,250 - sample_data_generator.py - Line: 300 - ERROR - !! Failed to upload to MinIO - HTTPConnectionPool(host='localhost', port=9000): Max retries exceeded with url: /raw/data/weather_data_2025-05-14.json (Caused by NewConnectionError('<urllib3.connection.HTTPConnection object at 0x7fbae51e9700>: Failed to establish a new connection: [Errno 111] Connection refused'))","chan":"stderr","logger":"task"}
{"timestamp":"2025-05-14T03:21:52.251436Z","level":"error","event":"2025-05-14 03:21:52,250 - sample_data_generator.py - Line: 345 - INFO - Uploaded to MinIO bucket 'raw', object 'data/weather_data_2025-05-14.json'","chan":"stderr","logger":"task"}
{"timestamp":"2025-05-14T03:21:52.342379","level":"error","event":"Task failed with exception","logger":"task","error_detail":[{"exc_type":"CalledProcessError","exc_value":"Command '['python', 'sample_data_generator.py', '--empty_rate', '47', '--error_rate', '23', '--credentials', '{\"MINIO_ROOT_USER\": \"admin\", \"MINIO_ROOT_PASSWORD\": \"admin123\", \"MINIO_ENDPOINT\": \"localhost:9000\", \"MINIO_KMS_SECRET_KEY\": \"my-minio-key:YWRtaW4xMjNhZG1pbjEyM2FkbWluMTIzYWRtaW4xMjM=\", \"MINIO_BUCKET_RAW\": \"raw\", \"MINIO_BUCKET_STAGING\": \"staging\", \"MINIO_BUCKET_CURATED\": \"curated\"}']' returned non-zero exit status 1.","exc_notes":[],"syntax_error":null,"is_cause":false,"frames":[{"filename":"/home/airflow/.local/lib/python3.12/site-packages/airflow/sdk/execution_time/task_runner.py","lineno":825,"name":"run"},{"filename":"/home/airflow/.local/lib/python3.12/site-packages/airflow/sdk/execution_time/task_runner.py","lineno":1088,"name":"_execute_task"},{"filename":"/home/airflow/.local/lib/python3.12/site-packages/airflow/sdk/bases/operator.py","lineno":408,"name":"wrapper"},{"filename":"/home/airflow/.local/lib/python3.12/site-packages/airflow/providers/standard/operators/python.py","lineno":212,"name":"execute"},{"filename":"/home/airflow/.local/lib/python3.12/site-packages/airflow/providers/standard/operators/python.py","lineno":235,"name":"execute_callable"},{"filename":"/home/airflow/.local/lib/python3.12/site-packages/airflow/sdk/execution_time/callback_runner.py","lineno":81,"name":"run"},{"filename":"/opt/airflow/dags/99_weather_data_generator_daily.py","lineno":89,"name":"run_generator"},{"filename":"/usr/local/lib/python3.12/subprocess.py","lineno":571,"name":"run"}]}]}
{"timestamp":"2025-05-14T03:38:34.802091","level":"info","event":"DAG bundles loaded: dags-folder","logger":"airflow.dag_processing.bundles.manager.DagBundlesManager"}
{"timestamp":"2025-05-14T03:38:34.802616","level":"info","event":"Filling up the DagBag from /opt/airflow/dags/99_weather_data_generator_daily.py","logger":"airflow.models.dagbag.DagBag"}
{"timestamp":"2025-05-14T03:38:34.815851","level":"info","event":"Secrets backends loaded for worker","count":1,"backend_classes":["EnvironmentVariablesBackend"],"logger":"supervisor"}
{"timestamp":"2025-05-14T03:38:34.857078","level":"warning","event":"Pydantic serializer warnings:\n  PydanticSerializationUnexpectedValue(Expected `str` - serialized value may not be as expected [input_value={'MINIO_ROOT_USER': 'admi...KET_CURATED': 'curated'}, input_type=dict])","category":"UserWarning","filename":"/home/airflow/.local/lib/python3.12/site-packages/pydantic/main.py","lineno":463,"logger":"py.warnings"}
{"timestamp":"2025-05-14T03:38:37.809845Z","level":"error","event":"2025-05-14 03:38:37,809 - sample_data_generator.py - Line: 51 - INFO - Initialized DataGenerator with empty_rate=9.0%, error_rate=21.0%","chan":"stderr","logger":"task"}
{"timestamp":"2025-05-14T03:38:37.810477Z","level":"error","event":"2025-05-14 03:38:37,809 - sample_data_generator.py - Line: 316 - INFO - Rates: empty_rate=9.0%%, error_rate=21.0%%","chan":"stderr","logger":"task"}
{"timestamp":"2025-05-14T03:38:37.832180Z","level":"error","event":"2025-05-14 03:38:37,831 - sample_data_generator.py - Line: 298 - INFO - Uploaded data/weather_data_2025-05-14.json to bucket 'raw'","chan":"stderr","logger":"task"}
{"timestamp":"2025-05-14T03:38:37.832712Z","level":"error","event":"2025-05-14 03:38:37,832 - sample_data_generator.py - Line: 345 - INFO - Uploaded to MinIO bucket 'raw', object 'data/weather_data_2025-05-14.json'","chan":"stderr","logger":"task"}
{"timestamp":"2025-05-14T03:38:37.919026","level":"info","event":"Done. Returned value was: None","logger":"airflow.task.operators.airflow.providers.standard.operators.python.PythonOperator"}
