{"timestamp":"2025-05-14T02:45:02.782995","level":"info","event":"DAG bundles loaded: dags-folder","logger":"airflow.dag_processing.bundles.manager.DagBundlesManager"}
{"timestamp":"2025-05-14T02:45:02.783526","level":"info","event":"Filling up the DagBag from /opt/airflow/dags/99_weather_data_generator_daily.py","logger":"airflow.models.dagbag.DagBag"}
{"timestamp":"2025-05-14T02:45:02.792240","level":"info","event":"Secrets backends loaded for worker","count":1,"backend_classes":["EnvironmentVariablesBackend"],"logger":"supervisor"}
{"timestamp":"2025-05-14T02:45:02.837801","level":"warning","event":"Pydantic serializer warnings:\n  PydanticSerializationUnexpectedValue(Expected `str` - serialized value may not be as expected [input_value={'MINIO_ROOT_USER': 'admi...KET_CURATED': 'curated'}, input_type=dict])","category":"UserWarning","filename":"/home/airflow/.local/lib/python3.12/site-packages/pydantic/main.py","lineno":463,"logger":"py.warnings"}
{"timestamp":"2025-05-14T02:45:03.372154Z","level":"error","event":"Traceback (most recent call last):","chan":"stderr","logger":"task"}
{"timestamp":"2025-05-14T02:45:03.372420Z","level":"error","event":"  File \"/opt/project/sample_data_generator.py\", line 9, in <module>","chan":"stderr","logger":"task"}
{"timestamp":"2025-05-14T02:45:03.373331Z","level":"error","event":"    from minio import Minio","chan":"stderr","logger":"task"}
{"timestamp":"2025-05-14T02:45:03.373679Z","level":"error","event":"ModuleNotFoundError: No module named 'minio'","chan":"stderr","logger":"task"}
{"timestamp":"2025-05-14T02:45:03.377225","level":"error","event":"Task failed with exception","logger":"task","error_detail":[{"exc_type":"CalledProcessError","exc_value":"Command '['python', 'sample_data_generator.py', '--empty_rate', '27', '--error_rate', '61', '--credentials', '{\"MINIO_ROOT_USER\": \"admin\", \"MINIO_ROOT_PASSWORD\": \"admin123\", \"MINIO_ENDPOINT\": \"localhost:9000\", \"MINIO_KMS_SECRET_KEY\": \"my-minio-key:YWRtaW4xMjNhZG1pbjEyM2FkbWluMTIzYWRtaW4xMjM=\", \"MINIO_BUCKET_RAW\": \"raw\", \"MINIO_BUCKET_STAGING\": \"staging\", \"MINIO_BUCKET_CURATED\": \"curated\"}']' returned non-zero exit status 1.","exc_notes":[],"syntax_error":null,"is_cause":false,"frames":[{"filename":"/home/airflow/.local/lib/python3.12/site-packages/airflow/sdk/execution_time/task_runner.py","lineno":825,"name":"run"},{"filename":"/home/airflow/.local/lib/python3.12/site-packages/airflow/sdk/execution_time/task_runner.py","lineno":1088,"name":"_execute_task"},{"filename":"/home/airflow/.local/lib/python3.12/site-packages/airflow/sdk/bases/operator.py","lineno":408,"name":"wrapper"},{"filename":"/home/airflow/.local/lib/python3.12/site-packages/airflow/providers/standard/operators/python.py","lineno":212,"name":"execute"},{"filename":"/home/airflow/.local/lib/python3.12/site-packages/airflow/providers/standard/operators/python.py","lineno":235,"name":"execute_callable"},{"filename":"/home/airflow/.local/lib/python3.12/site-packages/airflow/sdk/execution_time/callback_runner.py","lineno":81,"name":"run"},{"filename":"/opt/airflow/dags/99_weather_data_generator_daily.py","lineno":89,"name":"run_generator"},{"filename":"/usr/local/lib/python3.12/subprocess.py","lineno":571,"name":"run"}]}]}
{"timestamp":"2025-05-14T03:09:50.214721","level":"info","event":"DAG bundles loaded: dags-folder","logger":"airflow.dag_processing.bundles.manager.DagBundlesManager"}
{"timestamp":"2025-05-14T03:09:50.215158","level":"info","event":"Filling up the DagBag from /opt/airflow/dags/99_weather_data_generator_daily.py","logger":"airflow.models.dagbag.DagBag"}
{"timestamp":"2025-05-14T03:09:50.220877","level":"info","event":"Secrets backends loaded for worker","count":1,"backend_classes":["EnvironmentVariablesBackend"],"logger":"supervisor"}
{"timestamp":"2025-05-14T03:09:50.240371","level":"warning","event":"Pydantic serializer warnings:\n  PydanticSerializationUnexpectedValue(Expected `str` - serialized value may not be as expected [input_value={'MINIO_ROOT_USER': 'admi...KET_CURATED': 'curated'}, input_type=dict])","category":"UserWarning","filename":"/home/airflow/.local/lib/python3.12/site-packages/pydantic/main.py","lineno":463,"logger":"py.warnings"}
{"timestamp":"2025-05-14T03:09:51.736535Z","level":"error","event":"2025-05-14 03:09:51,736 - sample_data_generator.py - Line: 40 - WARNING - empty_rate + error_rate > 100; reducing error_rate","chan":"stderr","logger":"task"}
{"timestamp":"2025-05-14T03:09:51.740195Z","level":"error","event":"2025-05-14 03:09:51,739 - sample_data_generator.py - Line: 51 - INFO - Initialized DataGenerator with empty_rate=90.0%, error_rate=10.0%","chan":"stderr","logger":"task"}
{"timestamp":"2025-05-14T03:09:51.740665Z","level":"error","event":"2025-05-14 03:09:51,740 - sample_data_generator.py - Line: 316 - INFO - Rates: empty_rate=90.0%%, error_rate=10.0%%","chan":"stderr","logger":"task"}
{"timestamp":"2025-05-14T03:09:51.740993Z","level":"error","event":"2025-05-14 03:09:51,740 - sample_data_generator.py - Line: 324 - WARNING - Simulating empty JSON (rand=83.86<empty_rate)","chan":"stderr","logger":"task"}
{"timestamp":"2025-05-14T03:09:51.748391Z","level":"error","event":"2025-05-14 03:09:51,748 - connectionpool.py - Line: 868 - WARNING - Retrying (Retry(total=4, connect=None, read=None, redirect=None, status=None)) after connection broken by 'NewConnectionError('<urllib3.connection.HTTPConnection object at 0x7f6d72f4f800>: Failed to establish a new connection: [Errno 111] Connection refused')': /raw/data/weather_data_2025-05-14.json","chan":"stderr","logger":"task"}
{"timestamp":"2025-05-14T03:09:52.149294Z","level":"error","event":"2025-05-14 03:09:52,149 - connectionpool.py - Line: 868 - WARNING - Retrying (Retry(total=3, connect=None, read=None, redirect=None, status=None)) after connection broken by 'NewConnectionError('<urllib3.connection.HTTPConnection object at 0x7f6da70dfe00>: Failed to establish a new connection: [Errno 111] Connection refused')': /raw/data/weather_data_2025-05-14.json","chan":"stderr","logger":"task"}
{"timestamp":"2025-05-14T03:09:52.950958Z","level":"error","event":"2025-05-14 03:09:52,950 - connectionpool.py - Line: 868 - WARNING - Retrying (Retry(total=2, connect=None, read=None, redirect=None, status=None)) after connection broken by 'NewConnectionError('<urllib3.connection.HTTPConnection object at 0x7f6d72626c00>: Failed to establish a new connection: [Errno 111] Connection refused')': /raw/data/weather_data_2025-05-14.json","chan":"stderr","logger":"task"}
{"timestamp":"2025-05-14T03:09:54.550491Z","level":"error","event":"2025-05-14 03:09:54,550 - connectionpool.py - Line: 868 - WARNING - Retrying (Retry(total=1, connect=None, read=None, redirect=None, status=None)) after connection broken by 'NewConnectionError('<urllib3.connection.HTTPConnection object at 0x7f6d726271d0>: Failed to establish a new connection: [Errno 111] Connection refused')': /raw/data/weather_data_2025-05-14.json","chan":"stderr","logger":"task"}
{"timestamp":"2025-05-14T03:09:57.751615Z","level":"error","event":"2025-05-14 03:09:57,751 - connectionpool.py - Line: 868 - WARNING - Retrying (Retry(total=0, connect=None, read=None, redirect=None, status=None)) after connection broken by 'NewConnectionError('<urllib3.connection.HTTPConnection object at 0x7f6d72626660>: Failed to establish a new connection: [Errno 111] Connection refused')': /raw/data/weather_data_2025-05-14.json","chan":"stderr","logger":"task"}
{"timestamp":"2025-05-14T03:09:57.784533Z","level":"error","event":"2025-05-14 03:09:57,752 - sample_data_generator.py - Line: 300 - ERROR - !! Failed to upload to MinIO - HTTPConnectionPool(host='localhost', port=9000): Max retries exceeded with url: /raw/data/weather_data_2025-05-14.json (Caused by NewConnectionError('<urllib3.connection.HTTPConnection object at 0x7f6d72626c60>: Failed to establish a new connection: [Errno 111] Connection refused'))","chan":"stderr","logger":"task"}
{"timestamp":"2025-05-14T03:09:57.785573Z","level":"error","event":"2025-05-14 03:09:57,752 - sample_data_generator.py - Line: 345 - INFO - Uploaded to MinIO bucket 'raw', object 'data/weather_data_2025-05-14.json'","chan":"stderr","logger":"task"}
{"timestamp":"2025-05-14T03:09:57.830133","level":"error","event":"Task failed with exception","logger":"task","error_detail":[{"exc_type":"CalledProcessError","exc_value":"Command '['python', 'sample_data_generator.py', '--empty_rate', '90', '--error_rate', '21', '--credentials', '{\"MINIO_ROOT_USER\": \"admin\", \"MINIO_ROOT_PASSWORD\": \"admin123\", \"MINIO_ENDPOINT\": \"localhost:9000\", \"MINIO_KMS_SECRET_KEY\": \"my-minio-key:YWRtaW4xMjNhZG1pbjEyM2FkbWluMTIzYWRtaW4xMjM=\", \"MINIO_BUCKET_RAW\": \"raw\", \"MINIO_BUCKET_STAGING\": \"staging\", \"MINIO_BUCKET_CURATED\": \"curated\"}']' returned non-zero exit status 1.","exc_notes":[],"syntax_error":null,"is_cause":false,"frames":[{"filename":"/home/airflow/.local/lib/python3.12/site-packages/airflow/sdk/execution_time/task_runner.py","lineno":825,"name":"run"},{"filename":"/home/airflow/.local/lib/python3.12/site-packages/airflow/sdk/execution_time/task_runner.py","lineno":1088,"name":"_execute_task"},{"filename":"/home/airflow/.local/lib/python3.12/site-packages/airflow/sdk/bases/operator.py","lineno":408,"name":"wrapper"},{"filename":"/home/airflow/.local/lib/python3.12/site-packages/airflow/providers/standard/operators/python.py","lineno":212,"name":"execute"},{"filename":"/home/airflow/.local/lib/python3.12/site-packages/airflow/providers/standard/operators/python.py","lineno":235,"name":"execute_callable"},{"filename":"/home/airflow/.local/lib/python3.12/site-packages/airflow/sdk/execution_time/callback_runner.py","lineno":81,"name":"run"},{"filename":"/opt/airflow/dags/99_weather_data_generator_daily.py","lineno":89,"name":"run_generator"},{"filename":"/usr/local/lib/python3.12/subprocess.py","lineno":571,"name":"run"}]}]}
{"timestamp":"2025-05-14T03:23:53.209060","level":"info","event":"DAG bundles loaded: dags-folder","logger":"airflow.dag_processing.bundles.manager.DagBundlesManager"}
{"timestamp":"2025-05-14T03:23:53.209916","level":"info","event":"Filling up the DagBag from /opt/airflow/dags/99_weather_data_generator_daily.py","logger":"airflow.models.dagbag.DagBag"}
{"timestamp":"2025-05-14T03:23:53.218162","level":"info","event":"Secrets backends loaded for worker","count":1,"backend_classes":["EnvironmentVariablesBackend"],"logger":"supervisor"}
{"timestamp":"2025-05-14T03:23:53.239244","level":"warning","event":"Pydantic serializer warnings:\n  PydanticSerializationUnexpectedValue(Expected `str` - serialized value may not be as expected [input_value={'MINIO_ROOT_USER': 'admi...KET_CURATED': 'curated'}, input_type=dict])","category":"UserWarning","filename":"/home/airflow/.local/lib/python3.12/site-packages/pydantic/main.py","lineno":463,"logger":"py.warnings"}
{"timestamp":"2025-05-14T03:23:54.741282Z","level":"error","event":"2025-05-14 03:23:54,740 - sample_data_generator.py - Line: 51 - INFO - Initialized DataGenerator with empty_rate=47.0%, error_rate=23.0%","chan":"stderr","logger":"task"}
{"timestamp":"2025-05-14T03:23:54.741858Z","level":"error","event":"2025-05-14 03:23:54,741 - sample_data_generator.py - Line: 316 - INFO - Rates: empty_rate=47.0%%, error_rate=23.0%%","chan":"stderr","logger":"task"}
{"timestamp":"2025-05-14T03:23:54.753618Z","level":"error","event":"2025-05-14 03:23:54,753 - connectionpool.py - Line: 868 - WARNING - Retrying (Retry(total=4, connect=None, read=None, redirect=None, status=None)) after connection broken by 'NewConnectionError('<urllib3.connection.HTTPConnection object at 0x7f71b6afb380>: Failed to establish a new connection: [Errno 111] Connection refused')': /raw/data/weather_data_2025-05-14.json","chan":"stderr","logger":"task"}
{"timestamp":"2025-05-14T03:23:55.154681Z","level":"error","event":"2025-05-14 03:23:55,154 - connectionpool.py - Line: 868 - WARNING - Retrying (Retry(total=3, connect=None, read=None, redirect=None, status=None)) after connection broken by 'NewConnectionError('<urllib3.connection.HTTPConnection object at 0x7f71b7402ab0>: Failed to establish a new connection: [Errno 111] Connection refused')': /raw/data/weather_data_2025-05-14.json","chan":"stderr","logger":"task"}
{"timestamp":"2025-05-14T03:23:55.955910Z","level":"error","event":"2025-05-14 03:23:55,955 - connectionpool.py - Line: 868 - WARNING - Retrying (Retry(total=2, connect=None, read=None, redirect=None, status=None)) after connection broken by 'NewConnectionError('<urllib3.connection.HTTPConnection object at 0x7f71bc555cd0>: Failed to establish a new connection: [Errno 111] Connection refused')': /raw/data/weather_data_2025-05-14.json","chan":"stderr","logger":"task"}
{"timestamp":"2025-05-14T03:23:57.556950Z","level":"error","event":"2025-05-14 03:23:57,556 - connectionpool.py - Line: 868 - WARNING - Retrying (Retry(total=1, connect=None, read=None, redirect=None, status=None)) after connection broken by 'NewConnectionError('<urllib3.connection.HTTPConnection object at 0x7f71b6afae40>: Failed to establish a new connection: [Errno 111] Connection refused')': /raw/data/weather_data_2025-05-14.json","chan":"stderr","logger":"task"}
{"timestamp":"2025-05-14T03:24:00.757850Z","level":"error","event":"2025-05-14 03:24:00,757 - connectionpool.py - Line: 868 - WARNING - Retrying (Retry(total=0, connect=None, read=None, redirect=None, status=None)) after connection broken by 'NewConnectionError('<urllib3.connection.HTTPConnection object at 0x7f71b6afaff0>: Failed to establish a new connection: [Errno 111] Connection refused')': /raw/data/weather_data_2025-05-14.json","chan":"stderr","logger":"task"}
{"timestamp":"2025-05-14T03:24:00.779798Z","level":"error","event":"2025-05-14 03:24:00,758 - sample_data_generator.py - Line: 300 - ERROR - !! Failed to upload to MinIO - HTTPConnectionPool(host='localhost', port=9000): Max retries exceeded with url: /raw/data/weather_data_2025-05-14.json (Caused by NewConnectionError('<urllib3.connection.HTTPConnection object at 0x7f71b6afb050>: Failed to establish a new connection: [Errno 111] Connection refused'))","chan":"stderr","logger":"task"}
{"timestamp":"2025-05-14T03:24:00.780483Z","level":"error","event":"2025-05-14 03:24:00,758 - sample_data_generator.py - Line: 345 - INFO - Uploaded to MinIO bucket 'raw', object 'data/weather_data_2025-05-14.json'","chan":"stderr","logger":"task"}
{"timestamp":"2025-05-14T03:24:00.835853","level":"info","event":"Done. Returned value was: None","logger":"airflow.task.operators.airflow.providers.standard.operators.python.PythonOperator"}
{"timestamp":"2025-05-14T03:52:51.388739","level":"info","event":"DAG bundles loaded: dags-folder","logger":"airflow.dag_processing.bundles.manager.DagBundlesManager"}
{"timestamp":"2025-05-14T03:52:51.389278","level":"info","event":"Filling up the DagBag from /opt/airflow/dags/99_weather_data_generator_daily.py","logger":"airflow.models.dagbag.DagBag"}
{"timestamp":"2025-05-14T03:52:51.407158","level":"info","event":"Secrets backends loaded for worker","count":1,"backend_classes":["EnvironmentVariablesBackend"],"logger":"supervisor"}
{"timestamp":"2025-05-14T03:52:53.270855Z","level":"info","event":"2025-05-14 03:52:53,270 - sample_data_generator.py - Line: 51 - INFO - Initialized DataGenerator with empty_rate=49.0%, error_rate=24.0%","chan":"stdout","logger":"task"}
{"timestamp":"2025-05-14T03:52:53.271402Z","level":"info","event":"2025-05-14 03:52:53,270 - sample_data_generator.py - Line: 316 - INFO - Rates: empty_rate=49.0%%, error_rate=24.0%%","chan":"stdout","logger":"task"}
{"timestamp":"2025-05-14T03:52:53.294733Z","level":"info","event":"2025-05-14 03:52:53,294 - sample_data_generator.py - Line: 298 - INFO - Uploaded data/weather_data_2025-05-14.json to bucket 'raw'","chan":"stdout","logger":"task"}
{"timestamp":"2025-05-14T03:52:53.295302Z","level":"info","event":"2025-05-14 03:52:53,294 - sample_data_generator.py - Line: 345 - INFO - Uploaded to MinIO bucket 'raw', object 'data/weather_data_2025-05-14.json'","chan":"stdout","logger":"task"}
{"timestamp":"2025-05-14T03:52:53.386292","level":"info","event":"Done. Returned value was: None","logger":"airflow.task.operators.airflow.providers.standard.operators.python.PythonOperator"}
